<sdf version='1.7'>
  <world name='default'>
    <model name='ground_plane'>
      <static>1</static>
      <link name='link'>
        <collision name='collision'>
          <geometry>
            <plane>
              <normal>0 0 1</normal>
              <size>100 100</size>
            </plane>
          </geometry>
          <surface>
            <contact>
              <collide_bitmask>65535</collide_bitmask>
              <ode/>
            </contact>
            <friction>
              <ode>
                <mu>100</mu>
                <mu2>50</mu2>
              </ode>
              <torsional>
                <ode/>
              </torsional>
            </friction>
            <bounce/>
          </surface>
          <max_contacts>10</max_contacts>
        </collision>
        <visual name='visual'>
          <cast_shadows>0</cast_shadows>
          <geometry>
            <plane>
              <normal>0 0 1</normal>
              <size>100 100</size>
            </plane>
          </geometry>
          <material>
            <script>
              <uri>file://media/materials/scripts/gazebo.material</uri>
              <name>Gazebo/Grey</name>
            </script>
          </material>
        </visual>
        <self_collide>0</self_collide>
        <enable_wind>0</enable_wind>
        <kinematic>0</kinematic>
      </link>
    </model>
    <light name='sun' type='directional'>
      <cast_shadows>1</cast_shadows>
      <pose>0 0 10 0 -0 0</pose>
      <diffuse>0.8 0.8 0.8 1</diffuse>
      <specular>0.2 0.2 0.2 1</specular>
      <attenuation>
        <range>1000</range>
        <constant>0.9</constant>
        <linear>0.01</linear>
        <quadratic>0.001</quadratic>
      </attenuation>
      <direction>-0.5 0.1 -0.9</direction>
      <spot>
        <inner_angle>0</inner_angle>
        <outer_angle>0</outer_angle>
        <falloff>0</falloff>
      </spot>
    </light>
    <gui fullscreen='0'>
      <camera name='user_camera'>
        <pose>1.26946 1.1299 0.735228 0 0.283643 -2.69499</pose>
        <view_controller>ortho</view_controller>
        <projection_type>orthographic</projection_type>
      </camera>
    </gui>
    <gravity>0 0 0</gravity>
    <magnetic_field>6e-06 2.3e-05 -4.2e-05</magnetic_field>
    <atmosphere type='adiabatic'/>
    <physics type='ode'>
      <max_step_size>0.001</max_step_size>
      <real_time_factor>1</real_time_factor>
      <real_time_update_rate>1000</real_time_update_rate>
    </physics>
    <scene>
      <ambient>0.4 0.4 0.4 1</ambient>
      <background>0.7 0.7 0.7 1</background>
      <shadows>1</shadows>
    </scene>
    <wind/>
    <spherical_coordinates>
      <surface_model>EARTH_WGS84</surface_model>
      <latitude_deg>0</latitude_deg>
      <longitude_deg>0</longitude_deg>
      <elevation>0</elevation>
      <heading_deg>0</heading_deg>
    </spherical_coordinates>
    <model name='disarm'>
      <link name='Base'>
        <inertial>
          <pose>-0 0.016143 -0.008232 0 -0 0</pose>
          <mass>1.19576</mass>
          <inertia>
            <ixx>0.00713666</ixx>
            <ixy>2.19739e-10</ixy>
            <ixz>6.0134e-09</ixz>
            <iyy>0.0123084</iyy>
            <iyz>-0.000158909</iyz>
            <izz>0.00603427</izz>
          </inertia>
        </inertial>
        <collision name='Base_collision'>
          <pose>0 0 0 0 -0 0</pose>
          <geometry>
            <mesh>
              <scale>1 1 1</scale>
              <uri>/home/matt/disarm/disarm_ws/src/disarm_simulation/meshes/Base.dae</uri>
            </mesh>
          </geometry>
          <surface>
            <contact>
              <ode/>
            </contact>
            <bounce/>
            <friction>
              <torsional>
                <ode/>
              </torsional>
              <ode/>
            </friction>
          </surface>
          <max_contacts>10</max_contacts>
        </collision>
        <collision name='Base_fixed_joint_lump__GuidingRods_collision_1'>
          <pose>0.17102 0.1465 0 0 -0 0</pose>
          <geometry>
            <mesh>
              <scale>1 1 1</scale>
              <uri>/home/matt/disarm/disarm_ws/src/disarm_simulation/meshes/GuidingRods.dae</uri>
            </mesh>
          </geometry>
          <surface>
            <contact>
              <ode/>
            </contact>
            <bounce/>
            <friction>
              <torsional>
                <ode/>
              </torsional>
              <ode/>
            </friction>
          </surface>
          <max_contacts>10</max_contacts>
        </collision>
        <collision name='Base_fixed_joint_lump__LeadScrew_collision_2'>
          <pose>0 0 0.17416 3.14159 -0 1.5708</pose>
          <geometry>
            <mesh>
              <scale>1 1 1</scale>
              <uri>/home/matt/disarm/disarm_ws/src/disarm_simulation/meshes/LeadScrew.dae</uri>
            </mesh>
          </geometry>
          <surface>
            <contact>
              <ode/>
            </contact>
            <bounce/>
            <friction>
              <torsional>
                <ode/>
              </torsional>
              <ode/>
            </friction>
          </surface>
          <max_contacts>10</max_contacts>
        </collision>
        <collision name='Base_fixed_joint_lump__chaser_body_collision_3'>
          <pose>0 0 -0.065 0 -0 0</pose>
          <geometry>
            <box>
              <size>0.35 0.35 0.125</size>
            </box>
          </geometry>
          <surface>
            <contact>
              <ode/>
            </contact>
            <friction>
              <ode>
                <mu>0</mu>
                <mu2>0</mu2>
              </ode>
              <torsional>
                <ode/>
              </torsional>
            </friction>
            <bounce/>
          </surface>
          <max_contacts>10</max_contacts>
        </collision>
        <visual name='Base_visual'>
          <pose>0 0 0 0 -0 0</pose>
          <geometry>
            <mesh>
              <scale>1 1 1</scale>
              <uri>/home/matt/disarm/disarm_ws/src/disarm_simulation/meshes/Base.dae</uri>
            </mesh>
          </geometry>
        </visual>
        <visual name='Base_fixed_joint_lump__GuidingRods_visual_1'>
          <pose>0.17102 0.1465 0 0 -0 0</pose>
          <geometry>
            <mesh>
              <scale>1 1 1</scale>
              <uri>/home/matt/disarm/disarm_ws/src/disarm_simulation/meshes/GuidingRods.dae</uri>
            </mesh>
          </geometry>
        </visual>
        <visual name='Base_fixed_joint_lump__LeadScrew_visual_2'>
          <pose>0 0 0.17416 3.14159 -0 1.5708</pose>
          <geometry>
            <mesh>
              <scale>1 1 1</scale>
              <uri>/home/matt/disarm/disarm_ws/src/disarm_simulation/meshes/LeadScrew.dae</uri>
            </mesh>
          </geometry>
        </visual>
        <visual name='Base_fixed_joint_lump__chaser_body_visual_3'>
          <pose>0 0 -0.065 0 -0 0</pose>
          <geometry>
            <box>
              <size>0.35 0.35 0.125</size>
            </box>
          </geometry>
          <material>
            <script>
              <name>Gazebo/DarkGrey</name>
              <uri>file://media/materials/scripts/gazebo.material</uri>
            </script>
          </material>
        </visual>
        <gravity>1</gravity>
        <velocity_decay/>
        <self_collide>0</self_collide>
        <enable_wind>0</enable_wind>
        <kinematic>0</kinematic>
      </link>
      <joint name='innerGRJoint' type='prismatic'>
        <pose relative_to='Base'>0 0 0.27734 0 -0 0</pose>
        <parent>Base</parent>
        <child>InnerGuidingRods</child>
        <axis>
          <xyz>0 0 1</xyz>
          <limit>
            <lower>-0.1</lower>
            <upper>0</upper>
            <effort>1000</effort>
            <velocity>0.2</velocity>
          </limit>
          <dynamics>
            <spring_reference>0</spring_reference>
            <spring_stiffness>0</spring_stiffness>
          </dynamics>
        </axis>
      </joint>
      <link name='InnerGuidingRods'>
        <pose relative_to='innerGRJoint'>0 0 0 0 -0 0</pose>
        <inertial>
          <pose>0.009329 -0 -0.011234 0 -0 0</pose>
          <mass>0.696722</mass>
          <inertia>
            <ixx>0.00213463</ixx>
            <ixy>4.98727e-06</ixy>
            <ixz>-7.30317e-05</ixz>
            <iyy>0.00249608</iyy>
            <iyz>4.67675e-11</iyz>
            <izz>0.00374486</izz>
          </inertia>
        </inertial>
        <collision name='InnerGuidingRods_collision'>
          <pose>0 0 0 0 -0 0</pose>
          <geometry>
            <mesh>
              <scale>1 1 1</scale>
              <uri>/home/matt/disarm/disarm_ws/src/disarm_simulation/meshes/Sensors.dae</uri>
            </mesh>
          </geometry>
          <surface>
            <contact>
              <ode/>
            </contact>
            <bounce/>
            <friction>
              <torsional>
                <ode/>
              </torsional>
              <ode/>
            </friction>
          </surface>
          <max_contacts>10</max_contacts>
        </collision>
        <collision name='InnerGuidingRods_fixed_joint_lump__TopPlate_collision_1'>
          <pose>0 0 0 0 -0 0</pose>
          <geometry>
            <mesh>
              <scale>1 1 1</scale>
              <uri>/home/matt/disarm/disarm_ws/src/disarm_simulation/meshes/TopPlate.dae</uri>
            </mesh>
          </geometry>
          <surface>
            <contact>
              <ode/>
            </contact>
            <bounce/>
            <friction>
              <torsional>
                <ode/>
              </torsional>
              <ode/>
            </friction>
          </surface>
          <max_contacts>10</max_contacts>
        </collision>
        <collision name='InnerGuidingRods_fixed_joint_lump__OuterShaft_collision_2'>
          <pose>0 0 -0.105 0 -0 1.66345</pose>
          <geometry>
            <mesh>
              <scale>1 1 1</scale>
              <uri>/home/matt/disarm/disarm_ws/src/disarm_simulation/meshes/OuterShaft.dae</uri>
            </mesh>
          </geometry>
          <surface>
            <contact>
              <ode/>
            </contact>
            <bounce/>
            <friction>
              <torsional>
                <ode/>
              </torsional>
              <ode/>
            </friction>
          </surface>
          <max_contacts>10</max_contacts>
        </collision>
        <collision name='InnerGuidingRods_fixed_joint_lump__Prongs_collision_3'>
          <pose>-0.04053 -0.033295 0 0 -0 0.087041</pose>
          <geometry>
            <mesh>
              <scale>1 1 1</scale>
              <uri>/home/matt/disarm/disarm_ws/src/disarm_simulation/meshes/Actuators.dae</uri>
            </mesh>
          </geometry>
          <surface>
            <contact>
              <ode/>
            </contact>
            <bounce/>
            <friction>
              <torsional>
                <ode/>
              </torsional>
              <ode/>
            </friction>
          </surface>
          <max_contacts>10</max_contacts>
        </collision>
        <collision name='InnerGuidingRods_fixed_joint_lump__laz_base_collision_4'>
          <pose>0.065 0 0 0 -1.55 0</pose>
          <geometry>
            <box>
              <size>0.01 0.02 0.01</size>
            </box>
          </geometry>
          <surface>
            <contact>
              <ode/>
            </contact>
            <friction>
              <ode>
                <mu>0.2</mu>
                <mu2>0.2</mu2>
              </ode>
              <torsional>
                <ode/>
              </torsional>
            </friction>
            <bounce/>
          </surface>
          <max_contacts>10</max_contacts>
        </collision>
        <visual name='InnerGuidingRods_visual'>
          <pose>0 0 0 0 -0 0</pose>
          <geometry>
            <mesh>
              <scale>1 1 1</scale>
              <uri>/home/matt/disarm/disarm_ws/src/disarm_simulation/meshes/Sensors.dae</uri>
            </mesh>
          </geometry>
        </visual>
        <visual name='InnerGuidingRods_fixed_joint_lump__TopPlate_visual_1'>
          <pose>0 0 0 0 -0 0</pose>
          <geometry>
            <mesh>
              <scale>1 1 1</scale>
              <uri>/home/matt/disarm/disarm_ws/src/disarm_simulation/meshes/TopPlate.dae</uri>
            </mesh>
          </geometry>
        </visual>
        <visual name='InnerGuidingRods_fixed_joint_lump__OuterShaft_visual_2'>
          <pose>0 0 -0.105 0 -0 1.66345</pose>
          <geometry>
            <mesh>
              <scale>1 1 1</scale>
              <uri>/home/matt/disarm/disarm_ws/src/disarm_simulation/meshes/OuterShaft.dae</uri>
            </mesh>
          </geometry>
        </visual>
        <visual name='InnerGuidingRods_fixed_joint_lump__Prongs_visual_3'>
          <pose>-0.04053 -0.033295 0 0 -0 0.087041</pose>
          <geometry>
            <mesh>
              <scale>1 1 1</scale>
              <uri>/home/matt/disarm/disarm_ws/src/disarm_simulation/meshes/Actuators.dae</uri>
            </mesh>
          </geometry>
        </visual>
        <visual name='InnerGuidingRods_fixed_joint_lump__laz_base_visual_4'>
          <pose>0.065 0 0 0 -1.55 0</pose>
          <geometry>
            <box>
              <size>0.01 0.02 0.01</size>
            </box>
          </geometry>
          <material>
            <script>
              <name>Gazebo/Grey</name>
              <uri>file://media/materials/scripts/gazebo.material</uri>
            </script>
          </material>
        </visual>
        <gravity>1</gravity>
        <velocity_decay/>
        <self_collide>0</self_collide>
        <enable_wind>0</enable_wind>
        <kinematic>0</kinematic>
      </link>
      <joint name='SpringJoint' type='prismatic'>
        <pose relative_to='InnerGuidingRods'>0 0 -0.105 0 -0 1.6634</pose>
        <parent>InnerGuidingRods</parent>
        <child>Spring</child>
        <axis>
          <xyz>0 0 1</xyz>
          <limit>
            <lower>0</lower>
            <upper>0</upper>
            <effort>1000</effort>
            <velocity>0.2</velocity>
          </limit>
          <dynamics>
            <damping>20</damping>
            <friction>0</friction>
            <spring_reference>0</spring_reference>
            <spring_stiffness>0</spring_stiffness>
          </dynamics>
        </axis>
      </joint>
      <link name='Spring'>
        <pose relative_to='SpringJoint'>0 0 0 0 -0 0</pose>
        <inertial>
          <pose>0.000618 -3.3e-05 0.046355 0 -0 0</pose>
          <mass>0.0045128</mass>
          <inertia>
            <ixx>3.4299e-06</ixx>
            <ixy>-2.26257e-10</ixy>
            <ixz>5.85962e-10</ixz>
            <iyy>3.42575e-06</iyy>
            <iyz>1.08654e-08</iyz>
            <izz>1.24218e-06</izz>
          </inertia>
        </inertial>
        <collision name='Spring_collision'>
          <pose>0 0 0 0 -0 0</pose>
          <geometry>
            <mesh>
              <scale>1 1 1</scale>
              <uri>/home/matt/disarm/disarm_ws/src/disarm_simulation/meshes/Spring.dae</uri>
            </mesh>
          </geometry>
          <surface>
            <contact>
              <ode/>
            </contact>
            <bounce/>
            <friction>
              <torsional>
                <ode/>
              </torsional>
              <ode/>
            </friction>
          </surface>
          <max_contacts>10</max_contacts>
        </collision>
        <visual name='Spring_visual'>
          <pose>0 0 0 0 -0 0</pose>
          <geometry>
            <mesh>
              <scale>1 1 1</scale>
              <uri>/home/matt/disarm/disarm_ws/src/disarm_simulation/meshes/Spring.dae</uri>
            </mesh>
          </geometry>
        </visual>
        <self_collide>0</self_collide>
        <enable_wind>0</enable_wind>
        <kinematic>0</kinematic>
      </link>
      <joint name='lazRot' type='revolute'>
        <pose relative_to='InnerGuidingRods'>0.062501 0 5.2e-05 0 -1.55 0</pose>
        <parent>InnerGuidingRods</parent>
        <child>laz_rot</child>
        <axis>
          <xyz>0 0 1</xyz>
          <limit>
            <lower>-1e+16</lower>
            <upper>1e+16</upper>
          </limit>
          <dynamics>
            <damping>0</damping>
            <friction>0.1</friction>
            <spring_reference>0</spring_reference>
            <spring_stiffness>0</spring_stiffness>
          </dynamics>
        </axis>
      </joint>
      <link name='laz_rot'>
        <pose relative_to='lazRot'>0 0 0 0 -0 0</pose>
        <inertial>
          <pose>0 0 0 0 -0 0</pose>
          <mass>0.1</mass>
          <inertia>
            <ixx>3.33333e-06</ixx>
            <ixy>0</ixy>
            <ixz>0</ixz>
            <iyy>3.33333e-06</iyy>
            <iyz>0</iyz>
            <izz>5e-06</izz>
          </inertia>
        </inertial>
        <collision name='laz_rot_collision'>
          <pose>0 0 0 0 -0 0</pose>
          <geometry>
            <box>
              <size>0.01 0.02 0.01</size>
            </box>
          </geometry>
          <surface>
            <contact>
              <ode/>
            </contact>
            <friction>
              <ode>
                <mu>0.2</mu>
                <mu2>0.2</mu2>
              </ode>
              <torsional>
                <ode/>
              </torsional>
            </friction>
            <bounce/>
          </surface>
          <max_contacts>10</max_contacts>
        </collision>
        <visual name='laz_rot_visual'>
          <pose>0 0 0 0 -0 0</pose>
          <geometry>
            <box>
              <size>0.01 0.02 0.01</size>
            </box>
          </geometry>
          <material>
            <script>
              <name>Gazebo/Grey</name>
              <uri>file://media/materials/scripts/gazebo.material</uri>
            </script>
          </material>
        </visual>
        <gravity>1</gravity>
        <velocity_decay/>
        <sensor name='laz' type='ray'>
          <always_on>1</always_on>
          <pose>0.01 0 0.0025 1.5708 -0 0</pose>
          <visualize>1</visualize>
          <update_rate>30</update_rate>
          <ray>
            <noise>
              <type>gaussian</type>
              <mean>0</mean>
              <stddev>0.01</stddev>
            </noise>
            <scan>
              <horizontal>
                <samples>720</samples>
                <resolution>0.25</resolution>
                <min_angle>-0.392699</min_angle>
                <max_angle>0.392699</max_angle>
              </horizontal>
              <vertical>
                <samples>1</samples>
                <resolution>1</resolution>
                <min_angle>-0.15</min_angle>
                <max_angle>0.15</max_angle>
              </vertical>
            </scan>
            <range>
              <min>0.05</min>
              <max>15</max>
              <resolution>0.02</resolution>
            </range>
          </ray>
        </sensor>
        <self_collide>0</self_collide>
        <enable_wind>0</enable_wind>
        <kinematic>0</kinematic>
      </link>
      <plugin name='mysensor_plugin' filename='libmysensor_plugin.so'>
        <robotNamespace>/</robotNamespace>
      </plugin>
      <plugin name='plannar_mover_plugin' filename='libplannar_mover_plugin.so'>
        <robotNamespace>/</robotNamespace>
      </plugin>
      <static>0</static>
      <plugin name='disarm_plugin' filename='libdisarm_plugin.so'>
        <robotNamespace>/</robotNamespace>
      </plugin>
      <pose>0 0 0 0 -0 0</pose>
    </model>
    <model name='cubesat1U'>
      <link name='cubesat1U'>
        <inertial>
          <pose>0 -0.05 0 0 -0 0</pose>
          <mass>0.79077</mass>
          <inertia>
            <ixx>0.0011919</ixx>
            <ixy>1.4344e-19</ixy>
            <ixz>-7.6799e-20</ixz>
            <iyy>0.0011107</iyy>
            <iyz>-9.62757e-20</iyz>
            <izz>0.001254</izz>
          </inertia>
        </inertial>
        <collision name='cubesat1U_collision'>
          <pose>0 0 0 1.5708 -0 0</pose>
          <geometry>
            <mesh>
              <scale>1 1 1</scale>
              <uri>model://cubesat1U/meshes/cubesat1U.dae</uri>
            </mesh>
          </geometry>
          <surface>
            <contact>
              <ode/>
            </contact>
            <bounce/>
            <friction>
              <torsional>
                <ode/>
              </torsional>
              <ode/>
            </friction>
          </surface>
          <max_contacts>10</max_contacts>
        </collision>
        <visual name='cubesat1U_visual'>
          <pose>0 0 0 1.5708 -0 0</pose>
          <geometry>
            <mesh>
              <scale>1 1 1</scale>
              <uri>model://cubesat1U/meshes/cubesat1U.dae</uri>
            </mesh>
          </geometry>
        </visual>
        <self_collide>0</self_collide>
        <enable_wind>0</enable_wind>
        <kinematic>0</kinematic>
      </link>
      <pose>0.23578 0.521762 0 0 -0 0</pose>
    </model>
    <state world_name='default'>
      <sim_time>0 0</sim_time>
      <real_time>0 0</real_time>
      <wall_time>1615779521 541440939</wall_time>
      <iterations>0</iterations>
      <model name='cubesat1U'>
        <pose>0.118175 0.819565 0.42247 0 -0 0</pose>
        <scale>1 1 1</scale>
        <link name='cubesat1U'>
          <pose>0.118175 0.819565 0.42247 0 -0 0</pose>
          <velocity>0 0 0 0 -0 0</velocity>
          <acceleration>0 0 0 0 -0 0</acceleration>
          <wrench>0 0 0 0 -0 0</wrench>
        </link>
      </model>
      <model name='disarm'>
        <pose>0.00053 0.00053 0.389812 -1.59483 0 0</pose>
        <scale>1 1 1</scale>
        <link name='Base'>
          <pose>0.00053 0.00053 0.389812 -1.59483 0 0</pose>
          <velocity>0 0 0 0 -0 0</velocity>
          <acceleration>0 0 0 0 -0 0</acceleration>
          <wrench>0 0 0 0 -0 0</wrench>
        </link>
        <link name='InnerGuidingRods'>
          <pose>0.00053 0.27779 0.383148 -1.59483 0 0</pose>
          <velocity>0 0 0 0 -0 0</velocity>
          <acceleration>0 0 0 0 -0 0</acceleration>
          <wrench>0 0 0 0 -0 0</wrench>
        </link>
        <link name='Spring'>
          <pose>0.00053 0.17282 0.385671 1.82509 1.47513 -2.88841</pose>
          <velocity>0 0 0 0 -0 0</velocity>
          <acceleration>0 0 0 0 -0 0</acceleration>
          <wrench>0 0 0 0 -0 0</wrench>
        </link>
        <link name='laz_rot'>
          <pose>0.063031 0.277842 0.383147 -1.5713 0.024025 1.54999</pose>
          <velocity>0 0 0 0 -0 0</velocity>
          <acceleration>0 0 0 0 -0 0</acceleration>
          <wrench>0 0 0 0 -0 0</wrench>
        </link>
      </model>
      <model name='ground_plane'>
        <pose>0 0 0 0 -0 0</pose>
        <scale>1 1 1</scale>
        <link name='link'>
          <pose>0 0 0 0 -0 0</pose>
          <velocity>0 0 0 0 -0 0</velocity>
          <acceleration>0 0 0 0 -0 0</acceleration>
          <wrench>0 0 0 0 -0 0</wrench>
        </link>
      </model>
      <light name='sun'>
        <pose>0 0 10 0 -0 0</pose>
      </light>
    </state>
  </world>
</sdf>
